{"name": "test_vwo_login_negative", "status": "skipped", "statusDetails": {"message": "XFAIL reason: Failed TC\n\n_pytest.outcomes.XFailed: Failed TC", "trace": "setup = <selenium.webdriver.chrome.webdriver.WebDriver (session=\"9983b058d354aad901d4e12d68f40fbd\")>\n\n    @allure.epic(\"VWO Login Test\")\n    @allure.feature(\"TC#0 - VWO App Negative Test\")\n    @pytest.mark.negative\n    def test_vwo_login_negative(setup):\n        try:\n            driver=setup\n            login_page=LoginPage(driver)\n            login_page.login_to_vwo(user=\"vijayatester16@gmail.com\",pwd=\"Wingify@123\")\n>           error_msg_element=login_page.get_error_message_text()\n\ntest_vwo_login.py:27: \n_ _ _ _ _ _ _ _ _ _ _ _ _ _ _ _ _ _ _ _ _ _ _ _ _ _ _ _ _ _ _ _ _ _ _ _ _ _ _ _\n..\\pageObjects\\pom\\loginPage.py:51: in get_error_message_text\n    return self.get_error_message().text\n..\\pageObjects\\pom\\loginPage.py:42: in get_error_message\n    webdriver_wait(driver=self.driver, element_tuple=self.get_error_message())\n..\\pageObjects\\pom\\loginPage.py:42: in get_error_message\n    webdriver_wait(driver=self.driver, element_tuple=self.get_error_message())\nE   RecursionError: maximum recursion depth exceeded\n!!! Recursion detected (same locals & position)\n\nDuring handling of the above exception, another exception occurred:\n\nsetup = <selenium.webdriver.chrome.webdriver.WebDriver (session=\"9983b058d354aad901d4e12d68f40fbd\")>\n\n    @allure.epic(\"VWO Login Test\")\n    @allure.feature(\"TC#0 - VWO App Negative Test\")\n    @pytest.mark.negative\n    def test_vwo_login_negative(setup):\n        try:\n            driver=setup\n            login_page=LoginPage(driver)\n            login_page.login_to_vwo(user=\"vijayatester16@gmail.com\",pwd=\"Wingify@123\")\n            error_msg_element=login_page.get_error_message_text()\n            assert error_msg_element== \"Your email, password, IP address or location did not match\"\n    \n        except Exception as e:\n>           pytest.xfail(\"Failed TC\")\nE           _pytest.outcomes.XFailed: Failed TC\n\ntest_vwo_login.py:31: XFailed"}, "start": 1741679889866, "stop": 1741679891140, "uuid": "9a235a26-bed2-47e8-bd00-200feb4cbc53", "historyId": "d768d3d769f5652f534d483ce8b8f9ed", "testCaseId": "d768d3d769f5652f534d483ce8b8f9ed", "fullName": "tests.vwoLoginTests.test_vwo_login#test_vwo_login_negative", "labels": [{"name": "feature", "value": "TC#0 - VWO App Negative Test"}, {"name": "epic", "value": "VWO Login Test"}, {"name": "tag", "value": "negative"}, {"name": "parentSuite", "value": "tests.vwoLoginTests"}, {"name": "suite", "value": "test_vwo_login"}, {"name": "host", "value": "LAPTOP-OLURE44J"}, {"name": "thread", "value": "24792-MainThread"}, {"name": "framework", "value": "pytest"}, {"name": "language", "value": "cpython3"}, {"name": "package", "value": "tests.vwoLoginTests.test_vwo_login"}]}